Workbook
Name image: IF('Additional Config.'!$K$3<7,Images!$B$1,Images!$B$2)
Name image: IF('Additionnal Config. (2)'!$K$3<7,Images!$B$1,Images!$B$2)
Name image: IF([1]Config.!$K$3<7,[1]Images!$B$1,[1]Images!$B$2)
Name image: IF(Config.!$K$3<7,Images!$B$1,Images!$B$2)

Sheet Config.
J1: Top PCB: | K1: Not Installed | L1: =IF(VLOOKUP(K1,'[2]Supply Attribution'!AI42:AV74,14,FALSE)=0,"",VLOOKUP(K1,'[2]Supply Attribution'!AI42:AV74,14,FALSE)) | N1: When filling this form: | V1: Pack sku: | X1: 0610-221126-755 | AA1: Specification number: | AC1: SP755001
A2: =IF(RIGHT(L2,4)="128K","CORE FIXED - DO NOT UPDATE CORE VERSION","") | J2: Main PCB: | K2: 9920-201326 | L2: =IF(VLOOKUP(K2,'Supply Attribution'!P17:AD100,15,FALSE)=0,"",VLOOKUP(K2,'Supply Attribution'!P17:AD100,15,FALSE)) -> ASSY PCB IN.YE-V3FLX-5OP-A11-A22-A32-A41-A5DIR | N2: 1 - Select MODEL, REGION. Do not change these parameters thereafter! | R2: =MID(A1,4,3) | V2: Core Number: | X2: 9937-130074 | AA2: Customer software number: | AC2: 9938-755001
J3: Outputs: | K3: =VALUE(MID(J6,7,2)) -> 5 | L3: =IF(AND(K3<6,P9="A6"),"+1","") -> +1 | N3: 2 - If needed, change Main or Top PCB. Do not change these parameters thereafter! | V3: QSC number: | X3: 9919-101830 | AA3: Customer software revision: | AC3: 1
B4: F0-R01-0000-061 | J4: =IF(OR(J6="",J6="Not Set"),"Select Model and Region first","") | L4: =IF(RIGHT(L2,4)="128K","CORE FIXED","") | N4: 3 - Set optional Terminals, High and Low speed relays/tabs (if needed) | V4: QSC revision: | X4: A | AA4: Production software: | AC4: 9940-755001
B5: Document Revision: | G5: L | J5: ¯ MODEL ¯ | K5: ¯ REGION ¯ | L5: ¯ CONNECTION TYPE ¯ | N5: 4 - Fill the rest of the form. For dual pack configurations, place the slave config in the row below its master config. | AA5: Customer name: | AC5: Dynasty
B6: Short Form in.ye/yt flx | J6: in.ye-5 | K6: UL | L6: AMP | N6: TRUE | O6: TRUE
J7: Terminal block ID | K7: =IFERROR(IF($K$3>7,"Terminal Block A","--"),"--") -> -- | O7: -- | P7: Extra | R7: =IFERROR(IF($K$3<7,"--",IF($K$3>10,"Terminal Block B","Terminal Block C")),"--") -> -- | V7: =IFERROR(IF($K$3>10,"Terminal Block C","--"),"--") -> --
J8: Block configuration | K8: =IF(K7="--","--",IF(K3<4,"3-3-4-B","3-4-4-3")) -> -- | O8: -- | P8: -- | Q8: -- | R8: =IFERROR(IF(K3<6,"--",IF(K$3>10,"3-4-4-3","3-3-4-B")),"--") -> -- | V8: =IFERROR(IF(K3>10,"3-3-4-B","--"),"--") -> --
J9: Terminal position | K9: A1 | L9: A2 | M9: A3 | N9: =IF(ISERROR($K$3),"--",(IF($K$3=3,"--","A4"))) -> A4 | O9: =IF(ISERROR($K$3),"--",(IF($K$3>6,"--","A5"))) -> A5 | P9: A6 | Q9: Not Installed | R9: =IF(OR(R7="--",MID(R8,1,1)="B"),"--",CONCATENATE(RIGHT(R7,1),"1")) -> -- | S9: =IF(OR(R7="--",MID(R8,3,1)="B"),"--",CONCATENATE(RIGHT(R7,1),"2")) -> -- | T9: =IF(OR(R7="--",MID(R8,5,1)="B"),"--",CONCATENATE(RIGHT(R7,1),"3")) -> -- | U9: =IF(OR(R7="--",MID(R8,7,1)="B"),"--",CONCATENATE(RIGHT(R7,1),"4")) -> -- | V9: =IF(OR(V7="--",MID(V8,1,1)="B"),"--",CONCATENATE(RIGHT(V7,1),"1")) -> -- | W9: =IF(OR(V7="--",MID(V8,3,1)="B"),"--",CONCATENATE(RIGHT(V7,1),"2")) -> -- | X9: =IF(OR(V7="--",MID(V8,5,1)="B"),"--",CONCATENATE(RIGHT(V7,1),"3")) -> -- | Y9: =IF(AND(RIGHT(V7,1)="C",RIGHT(V8,1)="3"),"C4",IF(AND(RIGHT(V7,1)="B",RIGHT(V8,1)="3"),"B4","--")) -> -- | Z9: CP Usage | AA9: O3 Usage | AB9: O3 Pump | AC9: Filter Interface | AD9: Heater pump | AE9: Connectors
F10: Legend ® | J10: High speed | K10: =IF(ISERROR(VLOOKUP(CONCATENATE(K$9,"-H"),'Supply Attribution'!$O$5:$S$11,4,FALSE)),"--",VLOOKUP(CONCATENATE(K$9,"-H"),'Supply Attribution'!$O$5:$S$11,4,FALSE)) -> K1-P (P30,P31) | L10: =IF(ISERROR(VLOOKUP(CONCATENATE(L$9,"-H"),'Supply Attribution'!$O$5:$S$11,4,FALSE)),"--",VLOOKUP(CONCATENATE(L$9,"-H"),'Supply Attribution'!$O$5:$S$11,4,FALSE)) -> K3-P | M10: =IF(ISERROR(VLOOKUP(CONCATENATE(M$9,"-H"),'Supply Attribution'!$O$5:$S$11,4,FALSE)),"--",VLOOKUP(CONCATENATE(M$9,"-H"),'Supply Attribution'!$O$5:$S$11,4,FALSE)) -> K4-P | N10: =IF(ISERROR(VLOOKUP(CONCATENATE(N$9,"-H"),'Supply Attribution'!$O$5:$S$11,4,FALSE)),"--",VLOOKUP(CONCATENATE(N$9,"-H"),'Supply Attribution'!$O$5:$S$11,4,FALSE)) -> K6-P | O10: =IF(ISERROR(VLOOKUP(CONCATENATE(O$9,"-H"),'Supply Attribution'!$O$5:$S$11,4,FALSE)),"--",VLOOKUP(CONCATENATE(O$9,"-H"),'Supply Attribution'!$O$5:$S$11,4,FALSE)) -> (P49,P50) | P10: K26-P | Q10: =IF(ISERROR(VLOOKUP(CONCATENATE(Q$9,"-H"),'Supply Attribution'!$O$5:$S$11,4,FALSE)),"--",VLOOKUP(CONCATENATE(Q$9,"-H"),'Supply Attribution'!$O$5:$S$11,4,FALSE)) -> -- | R10: =IF(ISERROR(VLOOKUP(CONCATENATE(R$9,"-H"),'Supply Attribution'!$V$5:$Z$12,4,FALSE)),"--",VLOOKUP(CONCATENATE(R$9,"-H"),'Supply Attribution'!$V$5:$Z$12,4,FALSE)) -> -- | S10: =IF(ISERROR(VLOOKUP(CONCATENATE(S$9,"-H"),'Supply Attribution'!$V$5:$Z$12,4,FALSE)),"--",VLOOKUP(CONCATENATE(S$9,"-H"),'Supply Attribution'!$V$5:$Z$12,4,FALSE)) -> -- | T10: =IF(ISERROR(VLOOKUP(CONCATENATE(T$9,"-H"),'Supply Attribution'!$V$5:$Z$12,4,FALSE)),"--",VLOOKUP(CONCATENATE(T$9,"-H"),'Supply Attribution'!$V$5:$Z$12,4,FALSE)) -> -- | U10: =IF(ISERROR(VLOOKUP(CONCATENATE(U$9,"-H"),'Supply Attribution'!$V$5:$Z$12,4,FALSE)),"--",VLOOKUP(CONCATENATE(U$9,"-H"),'Supply Attribution'!$V$5:$Z$12,4,FALSE)) -> -- | V10: =IF(ISERROR(VLOOKUP(CONCATENATE(V$9,"-H"),'Supply Attribution'!$V$5:$Z$12,4,FALSE)),"--",VLOOKUP(CONCATENATE(V$9,"-H"),'Supply Attribution'!$V$5:$Z$12,4,FALSE)) -> -- | W10: =IF(ISERROR(VLOOKUP(CONCATENATE(W$9,"-H"),'Supply Attribution'!$V$5:$Z$12,4,FALSE)),"--",VLOOKUP(CONCATENATE(W$9,"-H"),'Supply Attribution'!$V$5:$Z$12,4,FALSE)) -> -- | X10: =IF(ISERROR(VLOOKUP(CONCATENATE(X$9,"-H"),'Supply Attribution'!$V$5:$Z$12,4,FALSE)),"--",VLOOKUP(CONCATENATE(X$9,"-H"),'Supply Attribution'!$V$5:$Z$12,4,FALSE)) -> -- | Y10: =IF(ISERROR(VLOOKUP(CONCATENATE(Y$9,"-H"),'Supply Attribution'!$V$5:$Z$12,4,FALSE)),"--",VLOOKUP(CONCATENATE(Y$9,"-H"),'Supply Attribution'!$V$5:$Z$12,4,FALSE)) -> -- | AE10: SKU OUT H
F11: Incorrect Setting | K11: =IF(K10="--","--",IF(ISNA(VLOOKUP(K10,'Supply Attribution'!$B$4:$G$20,5,FALSE)),"Not Installed",VLOOKUP(K10,'Supply Attribution'!$B$4:$G$20,5,FALSE))) -> OUT 4 | L11: =IF(L10="--","--",IF(ISNA(VLOOKUP(L10,'Supply Attribution'!$B$4:$G$20,5,FALSE)),"Not Installed",VLOOKUP(L10,'Supply Attribution'!$B$4:$G$20,5,FALSE))) -> OUT 1 | M11: =IF(M10="--","--",IF(ISNA(VLOOKUP(M10,'Supply Attribution'!$B$4:$G$20,5,FALSE)),"Not Installed",VLOOKUP(M10,'Supply Attribution'!$B$4:$G$20,5,FALSE))) -> OUT 2 | N11: =IF(N10="--","--",IF(ISNA(VLOOKUP(N10,'Supply Attribution'!$B$4:$G$20,5,FALSE)),"Not Installed",VLOOKUP(N10,'Supply Attribution'!$B$4:$G$20,5,FALSE))) -> OUT 3 | O11: =IF(O10="--","--",IF(ISNA(VLOOKUP(O10,'Supply Attribution'!$B$4:$G$20,5,FALSE)),"Not Installed",VLOOKUP(O10,'Supply Attribution'!$B$4:$G$20,5,FALSE))) -> DIRECT | P11: =IF(P10="--","--",IF(ISNA(VLOOKUP(P10,'Supply Attribution'!$B$4:$G$20,5,FALSE)),"Not Installed",VLOOKUP(P10,'Supply Attribution'!$B$4:$G$20,5,FALSE))) -> OUT 6 | Q11: =IF(Q10="--","--",IF(ISNA(VLOOKUP(Q10,'Supply Attribution'!$B$4:$G$20,5,FALSE)),"Not Installed",VLOOKUP(Q10,'Supply Attribution'!$B$4:$G$20,5,FALSE))) -> -- | R11: =IF(R10="--","--",IF(ISNA(VLOOKUP(R10,'Supply Attribution'!$B$4:$G$20,5,FALSE)),"Not Installed",VLOOKUP(R10,'Supply Attribution'!$B$4:$G$20,5,FALSE))) -> -- | ... Y11: =IF(Y10="--","--",IF(ISNA(VLOOKUP(Y10,'Supply Attribution'!$B$4:$G$20,5,FALSE)),"Not Installed",VLOOKUP(Y10,'Supply Attribution'!$B$4:$G$20,5,FALSE))) -> --
F12: Single Output | J12: Low speed | K12: =IF(ISERROR(VLOOKUP(CONCATENATE(K$9,"-L"),'Supply Attribution'!$P$5:$S$11,3,FALSE)),"--",VLOOKUP(CONCATENATE(K$9,"-L"),'Supply Attribution'!$P$5:$S$11,3,FALSE)) -> -- | L12: =IF(ISERROR(VLOOKUP(CONCATENATE(L$9,"-L"),'Supply Attribution'!$P$5:$S$11,3,FALSE)),"--",VLOOKUP(CONCATENATE(L$9,"-L"),'Supply Attribution'!$P$5:$S$11,3,FALSE)) -> K6-P | M12: =IF(ISERROR(VLOOKUP(CONCATENATE(M$9,"-L"),'Supply Attribution'!$P$5:$S$11,3,FALSE)),"--",VLOOKUP(CONCATENATE(M$9,"-L"),'Supply Attribution'!$P$5:$S$11,3,FALSE)) -> K2-P (P46,P47) | N12: =IF(ISERROR(VLOOKUP(CONCATENATE(N$9,"-L"),'Supply Attribution'!$P$5:$S$11,3,FALSE)),"--",VLOOKUP(CONCATENATE(N$9,"-L"),'Supply Attribution'!$P$5:$S$11,3,FALSE)) -> -- | O12: =IF(ISERROR(VLOOKUP(CONCATENATE(O$9,"-L"),'Supply Attribution'!$P$5:$S$11,3,FALSE)),"--",VLOOKUP(CONCATENATE(O$9,"-L"),'Supply Attribution'!$P$5:$S$11,3,FALSE)) -> -- | P12: =IF(ISERROR(VLOOKUP(CONCATENATE(P$9,"-L"),'Supply Attribution'!$P$5:$S$11,3,FALSE)),"--",VLOOKUP(CONCATENATE(P$9,"-L"),'Supply Attribution'!$P$5:$S$11,3,FALSE)) -> -- | Q12: =IF(ISERROR(VLOOKUP(CONCATENATE(Q$9,"-L"),'Supply Attribution'!$P$5:$S$11,3,FALSE)),"--",VLOOKUP(CONCATENATE(Q$9,"-L"),'Supply Attribution'!$P$5:$S$11,3,FALSE)) -> -- | R12: =IF(ISERROR(VLOOKUP(CONCATENATE(R$9,"-L"),'Supply Attribution'!$W$5:$Z$12,3,FALSE)),"--",VLOOKUP(CONCATENATE(R$9,"-L"),'Supply Attribution'!$W$5:$Z$12,3,FALSE)) -> -- | S12: =IF(ISERROR(VLOOKUP(CONCATENATE(S$9,"-L"),'Supply Attribution'!$W$5:$Z$12,3,FALSE)),"--",VLOOKUP(CONCATENATE(S$9,"-L"),'Supply Attribution'!$W$5:$Z$12,3,FALSE)) -> -- | T12: =IF(ISERROR(VLOOKUP(CONCATENATE(T$9,"-L"),'Supply Attribution'!$W$5:$Z$12,3,FALSE)),"--",VLOOKUP(CONCATENATE(T$9,"-L"),'Supply Attribution'!$W$5:$Z$12,3,FALSE)) -> -- | U12: =IF(ISERROR(VLOOKUP(CONCATENATE(U$9,"-L"),'Supply Attribution'!$W$5:$Z$12,3,FALSE)),"--",VLOOKUP(CONCATENATE(U$9,"-L"),'Supply Attribution'!$W$5:$Z$12,3,FALSE)) -> -- | V12: =IF(ISERROR(VLOOKUP(CONCATENATE(V$9,"-L"),'Supply Attribution'!$W$5:$Z$12,3,FALSE)),"--",VLOOKUP(CONCATENATE(V$9,"-L"),'Supply Attribution'!$W$5:$Z$12,3,FALSE)) -> -- | W12: =IF(ISERROR(VLOOKUP(CONCATENATE(W$9,"-L"),'Supply Attribution'!$W$5:$Z$12,3,FALSE)),"--",VLOOKUP(CONCATENATE(W$9,"-L"),'Supply Attribution'!$W$5:$Z$12,3,FALSE)) -> -- | X12: =IF(ISERROR(VLOOKUP(CONCATENATE(X$9,"-L"),'Supply Attribution'!$W$5:$Z$12,3,FALSE)),"--",VLOOKUP(CONCATENATE(X$9,"-L"),'Supply Attribution'!$W$5:$Z$12,3,FALSE)) -> -- | Y12: =IF(ISERROR(VLOOKUP(CONCATENATE(Y$9,"-L"),'Supply Attribution'!$W$5:$Z$12,3,FALSE)),"--",VLOOKUP(CONCATENATE(Y$9,"-L"),'Supply Attribution'!$W$5:$Z$12,3,FALSE)) -> -- | AE12: SKU OUT L
F13: Shared Output | K13: =IF(K12="--","--",IF(ISNA(VLOOKUP(K12,'Supply Attribution'!$B$4:$G$20,5,FALSE)),"Not Installed",VLOOKUP(K12,'Supply Attribution'!$B$4:$G$20,5,FALSE))) -> -- | L13: =IF(L12="--","--",IF(ISNA(VLOOKUP(L12,'Supply Attribution'!$B$4:$G$20,5,FALSE)),"Not Installed",VLOOKUP(L12,'Supply Attribution'!$B$4:$G$20,5,FALSE))) -> OUT 3 | M13: =IF(M12="--","--",IF(ISNA(VLOOKUP(M12,'Supply Attribution'!$B$4:$G$20,5,FALSE)),"Not Installed",VLOOKUP(M12,'Supply Attribution'!$B$4:$G$20,5,FALSE))) -> OUT 5 | N13: =IF(N12="--","--",IF(ISNA(VLOOKUP(N12,'Supply Attribution'!$B$4:$G$20,5,FALSE)),"Not Installed",VLOOKUP(N12,'Supply Attribution'!$B$4:$G$20,5,FALSE))) -> -- | O13: =IF(O12="--","--",IF(ISNA(VLOOKUP(O12,'Supply Attribution'!$B$4:$G$20,5,FALSE)),"Not Installed",VLOOKUP(O12,'Supply Attribution'!$B$4:$G$20,5,FALSE))) -> -- | P13: =IF(P12="--","--",IF(ISNA(VLOOKUP(P12,'Supply Attribution'!$B$4:$G$20,5,FALSE)),"Not Installed",VLOOKUP(P12,'Supply Attribution'!$B$4:$G$20,5,FALSE))) -> -- | Q13: =IF(Q12="--","--",IF(ISNA(VLOOKUP(Q12,'Supply Attribution'!$B$4:$G$20,5,FALSE)),"Not Installed",VLOOKUP(Q12,'Supply Attribution'!$B$4:$G$20,5,FALSE))) -> -- | R13: =IF(R12="--","--",IF(ISNA(VLOOKUP(R12,'Supply Attribution'!$B$4:$G$20,5,FALSE)),"Not Installed",VLOOKUP(R12,'Supply Attribution'!$B$4:$G$20,5,FALSE))) -> -- | ... Y13: =IF(Y12="--","--",IF(ISNA(VLOOKUP(Y12,'Supply Attribution'!$B$4:$G$20,5,FALSE)),"Not Installed",VLOOKUP(Y12,'Supply Attribution'!$B$4:$G$20,5,FALSE))) -> --
J14: Fuse (high speed) | K14: =IF(ISERROR(VLOOKUP(K10,'Supply Attribution'!$B$4:$G$20,6,FALSE)),"--",VLOOKUP(K10,'Supply Attribution'!$B$4:$G$20,6,FALSE)) -> F2 | L14: =IF(ISERROR(VLOOKUP(L10,'Supply Attribution'!$B$4:$G$20,6,FALSE)),"--",VLOOKUP(L10,'Supply Attribution'!$B$4:$G$20,6,FALSE)) -> F3 | M14: =IF(ISERROR(VLOOKUP(M10,'Supply Attribution'!$B$4:$G$20,6,FALSE)),"--",VLOOKUP(M10,'Supply Attribution'!$B$4:$G$20,6,FALSE)) -> F1 | N14: =IF(ISERROR(VLOOKUP(N10,'Supply Attribution'!$B$4:$G$20,6,FALSE)),"--",VLOOKUP(N10,'Supply Attribution'!$B$4:$G$20,6,FALSE)) -> F3 | O14: =IF(ISERROR(VLOOKUP(O10,'Supply Attribution'!$B$4:$G$20,6,FALSE)),"--",VLOOKUP(O10,'Supply Attribution'!$B$4:$G$20,6,FALSE)) -> F1 | P14: =IF(ISERROR(VLOOKUP(P10,'Supply Attribution'!$B$4:$G$20,6,FALSE)),"--",VLOOKUP(P10,'Supply Attribution'!$B$4:$G$20,6,FALSE)) -> F23 | Q14: =IF(ISERROR(VLOOKUP(Q10,'Supply Attribution'!$B$4:$G$20,6,FALSE)),"--",VLOOKUP(Q10,'Supply Attribution'!$B$4:$G$20,6,FALSE)) -> -- | R14: =IF(ISERROR(VLOOKUP(R10,'Supply Attribution'!$B$4:$G$20,6,FALSE)),"--",VLOOKUP(R10,'Supply Attribution'!$B$4:$G$20,6,FALSE)) -> -- | ... Y14: =IF(ISERROR(VLOOKUP(Y10,'Supply Attribution'!$B$4:$G$20,6,FALSE)),"--",VLOOKUP(Y10,'Supply Attribution'!$B$4:$G$20,6,FALSE)) -> --
J15: Fuse (low speed) | K15: =IF(ISERROR(VLOOKUP(K12,'Supply Attribution'!$B$4:$G$20,6,FALSE)),"--",VLOOKUP(K12,'Supply Attribution'!$B$4:$G$20,6,FALSE)) -> -- | L15: =IF(ISERROR(VLOOKUP(L12,'Supply Attribution'!$B$4:$G$20,6,FALSE)),"--",VLOOKUP(L12,'Supply Attribution'!$B$4:$G$20,6,FALSE)) -> F3 | M15: =IF(ISERROR(VLOOKUP(M12,'Supply Attribution'!$B$4:$G$20,6,FALSE)),"--",VLOOKUP(M12,'Supply Attribution'!$B$4:$G$20,6,FALSE)) -> F2 | N15: =IF(ISERROR(VLOOKUP(N12,'Supply Attribution'!$B$4:$G$20,6,FALSE)),"--",VLOOKUP(N12,'Supply Attribution'!$B$4:$G$20,6,FALSE)) -> -- | O15: =IF(ISERROR(VLOOKUP(O12,'Supply Attribution'!$B$4:$G$20,6,FALSE)),"--",VLOOKUP(O12,'Supply Attribution'!$B$4:$G$20,6,FALSE)) -> -- | P15: =IF(ISERROR(VLOOKUP(P12,'Supply Attribution'!$B$4:$G$20,6,FALSE)),"--",VLOOKUP(P12,'Supply Attribution'!$B$4:$G$20,6,FALSE)) -> -- | Q15: =IF(ISERROR(VLOOKUP(Q12,'Supply Attribution'!$B$4:$G$20,6,FALSE)),"--",VLOOKUP(Q12,'Supply Attribution'!$B$4:$G$20,6,FALSE)) -> -- | R15: =IF(ISERROR(VLOOKUP(R12,'Supply Attribution'!$B$4:$G$20,6,FALSE)),"--",VLOOKUP(R12,'Supply Attribution'!$B$4:$G$20,6,FALSE)) -> -- | ... Y15: =IF(ISERROR(VLOOKUP(Y12,'Supply Attribution'!$B$4:$G$20,6,FALSE)),"--",VLOOKUP(Y12,'Supply Attribution'!$B$4:$G$20,6,FALSE)) -> --
A16: ¯ Fuses and Line(s) MAX load ¯ | J16: Line (high speed) | K16: =IF(ISNA(VLOOKUP(CONCATENATE(K14,"Line"),'Supply Attribution'!$F$31:$G$37,2,FALSE)),"--",VLOOKUP(CONCATENATE(K14,"Line"),'Supply Attribution'!$F$31:$G$37,2,FALSE)) -> Line1 | L16: =IF(ISNA(VLOOKUP(CONCATENATE(L14,"Line"),'Supply Attribution'!$F$31:$G$37,2,FALSE)),"--",VLOOKUP(CONCATENATE(L14,"Line"),'Supply Attribution'!$F$31:$G$37,2,FALSE)) -> Line1 | M16: =IF(ISNA(VLOOKUP(CONCATENATE(M14,"Line"),'Supply Attribution'!$F$31:$G$37,2,FALSE)),"--",VLOOKUP(CONCATENATE(M14,"Line"),'Supply Attribution'!$F$31:$G$37,2,FALSE)) -> Line1 | N16: =IF(ISNA(VLOOKUP(CONCATENATE(N14,"Line"),'Supply Attribution'!$F$31:$G$37,2,FALSE)),"--",VLOOKUP(CONCATENATE(N14,"Line"),'Supply Attribution'!$F$31:$G$37,2,FALSE)) -> Line1 | O16: =IF(ISNA(VLOOKUP(CONCATENATE(O14,"Line"),'Supply Attribution'!$F$31:$G$37,2,FALSE)),"--",VLOOKUP(CONCATENATE(O14,"Line"),'Supply Attribution'!$F$31:$G$37,2,FALSE)) -> Line1 | P16: =IF(ISNA(VLOOKUP(CONCATENATE(P14,"Line"),'Supply Attribution'!$F$31:$G$37,2,FALSE)),"--",VLOOKUP(CONCATENATE(P14,"Line"),'Supply Attribution'!$F$31:$G$37,2,FALSE)) -> Line1 | Q16: =IF(ISNA(VLOOKUP(CONCATENATE(Q14,"Line"),'Supply Attribution'!$F$31:$G$37,2,FALSE)),"--",VLOOKUP(CONCATENATE(Q14,"Line"),'Supply Attribution'!$F$31:$G$37,2,FALSE)) -> -- | R16: =IF(ISNA(VLOOKUP(CONCATENATE(R14,"Line"),'Supply Attribution'!$F$31:$G$37,2,FALSE)),"--",VLOOKUP(CONCATENATE(R14,"Line"),'Supply Attribution'!$F$31:$G$37,2,FALSE)) -> -- | ... Y16: =IF(ISNA(VLOOKUP(CONCATENATE(Y14,"Line"),'Supply Attribution'!$F$31:$G$37,2,FALSE)),"--",VLOOKUP(CONCATENATE(Y14,"Line"),'Supply Attribution'!$F$31:$G$37,2,FALSE)) -> --
A17: Load control will be applied in some cases | J17: Line (low speed) | K17: =IF(ISNA(VLOOKUP(CONCATENATE(K15,"Line"),'Supply Attribution'!$F$31:$G$37,2,FALSE)),"--",VLOOKUP(CONCATENATE(K15,"Line"),'Supply Attribution'!$F$31:$G$37,2,FALSE)) -> -- | L17: =IF(ISNA(VLOOKUP(CONCATENATE(L15,"Line"),'Supply Attribution'!$F$31:$G$37,2,FALSE)),"--",VLOOKUP(CONCATENATE(L15,"Line"),'Supply Attribution'!$F$31:$G$37,2,FALSE)) -> Line1 | M17: =IF(ISNA(VLOOKUP(CONCATENATE(M15,"Line"),'Supply Attribution'!$F$31:$G$37,2,FALSE)),"--",VLOOKUP(CONCATENATE(M15,"Line"),'Supply Attribution'!$F$31:$G$37,2,FALSE)) -> Line1 | N17: =IF(ISNA(VLOOKUP(CONCATENATE(N15,"Line"),'Supply Attribution'!$F$31:$G$37,2,FALSE)),"--",VLOOKUP(CONCATENATE(N15,"Line"),'Supply Attribution'!$F$31:$G$37,2,FALSE)) -> -- | O17: =IF(ISNA(VLOOKUP(CONCATENATE(O15,"Line"),'Supply Attribution'!$F$31:$G$37,2,FALSE)),"--",VLOOKUP(CONCATENATE(O15,"Line"),'Supply Attribution'!$F$31:$G$37,2,FALSE)) -> -- | P17: =IF(ISNA(VLOOKUP(CONCATENATE(P15,"Line"),'Supply Attribution'!$F$31:$G$37,2,FALSE)),"--",VLOOKUP(CONCATENATE(P15,"Line"),'Supply Attribution'!$F$31:$G$37,2,FALSE)) -> -- | Q17: =IF(ISNA(VLOOKUP(CONCATENATE(Q15,"Line"),'Supply Attribution'!$F$31:$G$37,2,FALSE)),"--",VLOOKUP(CONCATENATE(Q15,"Line"),'Supply Attribution'!$F$31:$G$37,2,FALSE)) -> -- | R17: =IF(ISNA(VLOOKUP(CONCATENATE(R15,"Line"),'Supply Attribution'!$F$31:$G$37,2,FALSE)),"--",VLOOKUP(CONCATENATE(R15,"Line"),'Supply Attribution'!$F$31:$G$37,2,FALSE)) -> -- | ... Y17: =IF(ISNA(VLOOKUP(CONCATENATE(Y15,"Line"),'Supply Attribution'!$F$31:$G$37,2,FALSE)),"--",VLOOKUP(CONCATENATE(Y15,"Line"),'Supply Attribution'!$F$31:$G$37,2,FALSE)) -> --
A18: F1 | B18: F2 | C18: F3 | D18: F21 | E18: F22 | F18: F23 | G18: Line1 | H18: =IF(AND(K6="CE",T59<>"1 Phase"),"Line2","") | I18: =IF(AND($K$6="CE",T59="3 Phases"),"Line3","") | Z18: CP Usage | AA18: O3 Usage | AB18: O3 Pump | AC18: Filter Interface | AD18: Heater pump
A19: =VLOOKUP(CONCATENATE(A18,"CURRENT"),'Supply Attribution'!$F22:$G30,2,FALSE) -> 15 | B19: =VLOOKUP(CONCATENATE(B18,"CURRENT"),'Supply Attribution'!$F22:$G30,2,FALSE) -> 15 | C19: =VLOOKUP(CONCATENATE(C18,"CURRENT"),'Supply Attribution'!$F22:$G30,2,FALSE) -> 24 | D19: =VLOOKUP(CONCATENATE(D18,"CURRENT"),'Supply Attribution'!$F22:$G30,2,FALSE) -> N/A | E19: =VLOOKUP(CONCATENATE(E18,"CURRENT"),'Supply Attribution'!$F22:$G30,2,FALSE) -> N/A | F19: =VLOOKUP(CONCATENATE(F18,"CURRENT"),'Supply Attribution'!$F22:$G30,2,FALSE) -> N/A | G19: =IF(AND(K6="CE",T59="2 phases"),MIN(20,T60),IF(AND(K6="CE",T59="3 Phases"),MIN(16,T60),MIN(48,T60))) -> 48 | H19: =IF(OR(K6="UL",T59="1 phase"),"",IF(T59="2 Phases",MIN(20,T60),MIN(16,T60))) | I19: =IF(AND(K6="CE",T59="3 Phases"),MIN(T60,16),"") | J19: Typical | K19: O3/CP | L19: P2_1SP | M19: P1_2SP | N19: P3_1SP | O19: DIRECT | P19: BL | Q19: -- | R19: -- | S19: P4_2SP | T19: P5_1SP | U19: BL | V19: DIRECT 2 | W19: CP | X19: P3_2SP | Y19: -- | Z19: Standard | AA19: ON when filtering | AB19: CP | AC19: With CP | AD19: CP
A20: =IF($K$6="CE",CONCATENATE("Heater on ",'Supply Attribution'!G20),"") | F20: =IF(AND(X86<>"Not Set",X86<>""),CONCATENATE("Heat Pump on ",X87),"") -> Heat Pump on Not Set | G20: =IF($K$6="UL","Heater on Line1","") -> Heater on Line1
